<?xml version="1.0"?>



<robot xmlns:xacro="http://ros.org/wiki/xacro" name="thor">
  <property name="M_PI" value="3.1415926535897931" />
  <link name="thor_base_link">
    <visual>
      <geometry>
        <mesh filename="package://thor_description/meshes/thor_base_link.stl"/>
      </geometry>
      <origin xyz="0 0 0" rpy="0 0 0"/>
      <material name="yellow">
        <color rgba="1 1 0 1"/>
      </material>
    </visual>
  </link>

  <link name="thor_art1_link">
    <visual>
      <geometry>
        <mesh filename="package://thor_description/meshes/thor_art1_link.stl"/>
      </geometry>
      <origin xyz="0 0 0" rpy="0 0 0"/>
      <material name="blue">
        <color rgba="0 0 1 1"/>
      </material>
    </visual>
  </link>
  <link name="thor_art2_link">
    <visual>
      <geometry>
        <mesh filename="package://thor_description/meshes/thor_art2_link.stl"/>	
      </geometry>
      <origin xyz="0 .055 0" rpy="0 0 0"/>
      <material name="green">
        <color rgba="0 1 0 1"/>
      </material>
    </visual>
  </link>

  <link name="thor_art3_link" >
    <visual>
    	<geometry>
      	  <mesh filename="package://thor_description/meshes/thor_art3_link.stl"/>
	</geometry>
      	<origin xyz="0 -.0375 0" rpy="0 0 0"/>
      	<material name="yellow">
        <color rgba="1 1 0 1"/>
        </material>
    </visual>
  </link>

  <link name="thor_art4_link">
    <visual>
      <geometry>
	<mesh filename="package://thor_description/meshes/thor_art4_link.stl"/>
      </geometry>
      <origin xyz="0 -.0025 0" rpy="0 0 0"/>
      <material name="red">
        <color rgba="1 0 0 1"/>
      </material>
    </visual>
  </link>


  <link name="thor_art5_link">
    <visual>
      <geometry>
	<mesh filename="package://thor_description/meshes/thor_art5_link.stl"/>        
      </geometry>
      <origin xyz="0 0 0" rpy="0 0 0"/>
      <material name="yellow">
        <color rgba="1 1 0 1"/>
      </material>
    </visual>
  </link>

  <link name="thor_art6_link">
    <visual>
      <geometry>
        <mesh filename="package://thor_description/meshes/thor_art6_link.stl"/>
      </geometry>
      <origin xyz="0 0 0" rpy="0 0 0"/>
      <material name="blue">
        <color rgba="0 0 1 1"/>
      </material>
    </visual>
  </link>

  <joint name="thor_art1_joint" type="revolute">
    <parent link="thor_base_link"/>
    <child link="thor_art1_link"/>
    <origin xyz="0 0 .105" rpy="0 0 0" />
    <axis xyz="0 0 1" />
    <limit effort="1.0" lower="-${M_PI}" upper="${M_PI}" velocity="0.5"/>
  </joint>

  <joint name="thor_art2_joint" type="revolute">
    <parent link="thor_art1_link"/>
    <child link="thor_art2_link"/>
    <origin xyz="0 0 .100" rpy="0 0 0" />
    <axis xyz="0 1 0" />
    <limit effort="1.0" lower="-${M_PI/2}" upper="${M_PI/2}" velocity="0.5"/>
  </joint>

  <joint name="thor_art3_joint" type="revolute">
    <parent link="thor_art2_link"/>
    <child link="thor_art3_link"/>
    <origin xyz="0 0 .160" rpy="0 0 0" />
    <axis xyz="0 1 0" />
    <limit effort="1.0" lower="-${M_PI}" upper="${M_PI}" velocity="0.5"/>
  </joint>

  <joint name="thor_art4_joint" type="revolute">
    <parent link="thor_art3_link"/>
    <child link="thor_art4_link"/>
    <origin xyz="0 0 .090" rpy="0 0 0" />
    <axis xyz="0 0 1" />
    <limit effort="1.0" lower="-${M_PI}" upper="${M_PI}" velocity="0.5"/>
  </joint>

  <joint name="thor_art5_joint" type="revolute">
    <parent link="thor_art4_link"/>
    <child link="thor_art5_link"/>
    <origin xyz="0 0 0.100" rpy="0 0 0" />
    <axis xyz="0 1 0" />
    <limit effort="1.0" lower="-${M_PI/2}" upper="${M_PI/2}" velocity="0.5"/>
  </joint>

  <joint name="thor_art6_joint" type="revolute">
    <parent link="thor_art5_link"/>
    <child link="thor_art6_link"/>
    <origin xyz="0 0 .070" rpy="0 0 0" />
    <axis xyz="0 0 1" />
    <limit effort="1000.0" lower="-${M_PI}" upper="${M_PI}" velocity="0.5"/>
  </joint>

</robot>
